Workbook

Sheet 5w5完全提取
A1: 佳稚年龄 | B1: 保单年度终结 | C1: 缴付保费总额 | D1: 现金提取金额(1),(2) | E1: 现金提取后之基本金额 | F1: 现金提取后之退保发还金额
F2: 保证金额(2) | G2: 非保证金额 | I2: 总额 (A)+(B)+(C)
F3: 保证现金价值 (A) | G3: 复归红利 (B) | H3: 终期分红 (C)
A4: ='5w5 18年调增提取'!B5 -> 42 | B4: 1 | C4: 50000 | D4: 0 | E4: 512296 | F4: 51 | G4: 0 | H4: 0 | I4: 51
A5: ='5w5 18年调增提取'!B6 -> 43 | B5: 2 | C5: 100000 | D5: 0 | E5: 512296 | F5: 51 | G5: 0 | H5: 0 | I5: 51
A6: ='5w5 18年调增提取'!B7 -> 44 | B6: 3 | C6: 150000 | D6: 0 | E6: 512296 | F6: 13320 | G6: 4150 | H6: 7747 | I6: 25216
A7: ='5w5 18年调增提取'!B8 -> 45 | B7: 4 | C7: 200000 | D7: 0 | E7: 512296 | F7: 37398 | G7: 8361 | H7: 17182 | I7: 62941
A8: ='5w5 18年调增提取'!B9 -> 46 | B8: 5 | C8: 250000 | D8: 0 | E8: 512296 | F8: 70697 | G8: 12636 | H8: 34121 | I8: 117454
A9: ='5w5 18年调增提取'!B10 -> 47 | B9: 6 | C9: 250000 | D9: 0 | E9: 512296 | F9: 93238 | G9: 16976 | H9: 109559 | I9: 219773
A10: ='5w5 18年调增提取'!B11 -> 48 | B10: 7 | C10: 250000 | D10: 0 | E10: 512296 | F10: 115267 | G10: 21380 | H10: 115808 | I10: 252454
A11: ='5w5 18年调增提取'!B12 -> 49 | B11: 8 | C11: 250000 | D11: 0 | E11: 512296 | F11: 148566 | G11: 25850 | H11: 116778 | I11: 291194
A12: ='5w5 18年调增提取'!B13 -> 50 | B12: 9 | C12: 250000 | D12: 0 | E12: 512296 | F12: 153177 | G12: 30387 | H12: 127531 | I12: 311095
A13: ='5w5 18年调增提取'!B14 -> 51 | B13: 10 | C13: 250000 | D13: 0 | E13: 512296 | F13: 157275 | G13: 31337 | H13: 140257 | I13: 328869
A14: ='5w5 18年调增提取'!B15 -> 52 | B14: 11 | C14: 250000 | D14: 0 | E14: 512296 | F14: 162398 | G14: 32310 | H14: 157936 | I14: 352643
A15: ='5w5 18年调增提取'!B16 -> 53 | B15: 12 | C15: 250000 | D15: 0 | E15: 512296 | F15: 167008 | G15: 33306 | H15: 177321 | I15: 377635
... A62: ='5w5 18年调增提取'!B63 -> 100 | B62: 59 | C62: 0 | D62: 33584 | E62: 0 | F62: 0 | G62: 0 | H62: 0 | I62: 0

Sheet 5w5 18年调增提取
A1: 妈妈年龄 | B1: 佳稚年龄 | C1: 保单年度终结 | D1: 缴付保费总额 | E1: 现金提取金额(1),(2) | F1: 现金提取后之基本金额 | G1: 现金提取后之退保发还金额
G2: 保证金额(2) | H2: 非保证金额 | J2: 总额 (A)+(B)+(C)
G3: 保证现金价值 (A) | H3: 复归红利 (B) | I3: 终期分红 (C) | L3: 保单年度 | M3: 保费投入 | N3: 提取金额 | O3: 优惠金额 | P3: 退保现金价值 | Q3: 现金流
L4: 0 | M4: =-D5 -> -50000 | Q4: =M4+N4+P4+O4 -> -50000 | T4: 0.14
A5: ='提取参考：第18年15%持续提取'!A5 -> 68 | B5: 42 | C5: 1 | D5: 50000 | E5: 0 | F5: 512296 | G5: 51 | H5: 0 | I5: 0 | J5: 51 | L5: =C5 -> 1 | M5: =M4 -> -50000 | O5: =D5*T4 -> 7000 | Q5: =M5+N5+P5+O5 -> -43000
A6: ='提取参考：第18年15%持续提取'!A6 -> 69 | B6: 43 | C6: 2 | D6: 100000 | E6: 0 | F6: 512296 | G6: 51 | H6: 0 | I6: 0 | J6: 51 | L6: =C6 -> 2 | M6: =M5 -> -50000 | Q6: =M6+N6+P6+O6 -> -50000
A7: ='提取参考：第18年15%持续提取'!A7 -> 70 | B7: 44 | C7: 3 | D7: 150000 | E7: 0 | F7: 512296 | G7: 13320 | H7: 4150 | I7: 7747 | J7: 25216 | L7: =C7 -> 3 | M7: =M6 -> -50000 | Q7: =M7+N7+P7+O7 -> -50000
A8: ='提取参考：第18年15%持续提取'!A8 -> 71 | B8: 45 | C8: 4 | D8: 200000 | E8: 0 | F8: 512296 | G8: 37398 | H8: 8361 | I8: 17182 | J8: 62941 | L8: =C8 -> 4 | M8: =M7 -> -50000 | Q8: =M8+N8+P8+O8 -> -50000
A9: ='提取参考：第18年15%持续提取'!A9 -> 72 | B9: 46 | C9: 5 | D9: 250000 | E9: 0 | F9: 512296 | G9: 70697 | H9: 12636 | I9: 34121 | J9: 117454 | L9: =C9 -> 5 | Q9: =M9+N9+P9+O9 -> 0
A10: ='提取参考：第18年15%持续提取'!A10 -> 73 | B10: 47 | C10: 6 | D10: 250000 | E10: 0 | F10: 512296 | G10: 93238 | H10: 16976 | I10: 109559 | J10: 219773 | L10: =C10 -> 6 | N10: =E10 -> 0 | Q10: =M10+N10+P10+O10 -> 0
A11: ='提取参考：第18年15%持续提取'!A11 -> 74 | B11: 48 | C11: 7 | D11: 250000 | E11: 0 | F11: 512296 | G11: 115267 | H11: 21380 | I11: 115808 | J11: 252454 | L11: =C11 -> 7 | N11: =E11 -> 0 | Q11: =M11+N11+P11+O11 -> 0
A12: ='提取参考：第18年15%持续提取'!A12 -> 75 | B12: 49 | C12: 8 | D12: 250000 | E12: 0 | F12: 512296 | G12: 148566 | H12: 25850 | I12: 116778 | J12: 291194 | L12: =C12 -> 8 | N12: =E12 -> 0 | Q12: =M12+N12+P12+O12 -> 0
A13: ='提取参考：第18年15%持续提取'!A13 -> 76 | B13: 50 | C13: 9 | D13: 250000 | E13: 0 | F13: 512296 | G13: 153177 | H13: 30387 | I13: 127531 | J13: 311095 | L13: =C13 -> 9 | N13: =E13 -> 0 | Q13: =M13+N13+P13+O13 -> 0
A14: ='提取参考：第18年15%持续提取'!A14 -> 77 | B14: 51 | C14: 10 | D14: 250000 | E14: 0 | F14: 512296 | G14: 157275 | H14: 31337 | I14: 140257 | J14: 328869 | L14: =C14 -> 10 | N14: =E14 -> 0 | Q14: =M14+N14+P14+O14 -> 0
A15: ='提取参考：第18年15%持续提取'!A15 -> 78 | B15: 52 | C15: 11 | D15: 250000 | E15: 0 | F15: 512296 | G15: 162398 | H15: 32310 | I15: 157936 | J15: 352643 | L15: =C15 -> 11 | N15: =E15 -> 0 | Q15: =M15+N15+P15+O15 -> 0
A16: ='提取参考：第18年15%持续提取'!A16 -> 79 | B16: 53 | C16: 12 | D16: 250000 | E16: 0 | F16: 512296 | G16: 167008 | H16: 33306 | I16: 177321 | J16: 377635 | L16: =C16 -> 12 | N16: =E16 -> 0 | Q16: =M16+N16+P16+O16 -> 0
A17: ='提取参考：第18年15%持续提取'!A17 -> 80 | B17: 54 | C17: 13 | D17: 250000 | E17: 0 | F17: 512296 | G17: 172131 | H17: 34327 | I17: 197878 | J17: 404336 | L17: =C17 -> 13 | N17: =E17 -> 0 | Q17: =M17+N17+P17+O17 -> 0
A18: ='提取参考：第18年15%持续提取'!A18 -> 81 | B18: 55 | C18: 14 | D18: 250000 | E18: 0 | F18: 512296 | G18: 177254 | H18: 35373 | I18: 221258 | J18: 433886 | L18: =C18 -> 14 | N18: =E18 -> 0 | Q18: =M18+N18+P18+O18 -> 0
A19: ='提取参考：第18年15%持续提取'!A19 -> 82 | B19: 56 | C19: 15 | D19: 250000 | E19: 0 | F19: 512296 | G19: 182377 | H19: 36444 | I19: 246384 | J19: 465206 | L19: =C19 -> 15 | N19: =E19 -> 0 | Q19: =M19+N19+P19+O19 -> 0
A20: ='提取参考：第18年15%持续提取'!A20 -> 83 | B20: 57 | C20: 16 | D20: 250000 | E20: 0 | F20: 512296 | G20: 194672 | H20: 37542 | I20: 268321 | J20: 500536 | L20: =C20 -> 16 | N20: =E20 -> 0 | Q20: =M20+N20+P20+O20 -> 0
A21: ='提取参考：第18年15%持续提取'!A21 -> 84 | B21: 58 | C21: 17 | D21: 250000 | E21: 0 | F21: 512296 | G21: 207480 | H21: 38667 | I21: 292561 | J21: 538708 | L21: =C21 -> 17 | N21: =E21 -> 0 | Q21: =M21+N21+P21+O21 -> 0
... A37: ='提取参考：第18年15%持续提取'!A37 -> 100 | B37: 74 | C37: 33 | D37: 165527 | E37: 30282 | F37: 338155 | G37: 172121 | H37: 0 | I37: 867030 | J37: 1039151 | L37: =C37 -> 33 | N37: =E37 -> 30282 | Q37: =M37+N37+P37+O37 -> 30282
B38: 75 | C38: 34 | D38: 160975 | E38: 30888 | F38: 328856 | G38: 168374 | H38: 0 | I38: 905998 | J38: 1074373 | L38: =C38 -> 34 | N38: =E38 -> 30888 | Q38: =M38+N38+P38+O38 -> 30888
B39: 76 | C39: 35 | D39: 156608 | E39: 31505 | F39: 319934 | G39: 164766 | H39: 0 | I39: 946366 | J39: 1111133 | L39: =C39 -> 35 | N39: =E39 -> 31505 | Q39: =M39+N39+P39+O39 -> 31505
B40: 77 | C40: 36 | D40: 152418 | E40: 32136 | F40: 311375 | G40: 160981 | H40: 0 | I40: 988616 | J40: 1149596 | L40: =C40 -> 36 | N40: =E40 -> 32136 | Q40: =M40+N40+P40+O40 -> 32136
B41: 78 | C41: 37 | D41: 148398 | E41: 32778 | F41: 303162 | G41: 157947 | H41: 0 | I41: 1031659 | J41: 1189606 | L41: =C41 -> 37 | N41: =E41 -> 32778 | Q41: =M41+N41+P41+O41 -> 32778
B42: 79 | C42: 38 | D42: 144540 | E42: 33434 | F42: 295281 | G42: 155022 | H42: 0 | I42: 1076594 | J42: 1231616 | L42: =C42 -> 38 | N42: =E42 -> 33434 | Q42: =M42+N42+P42+O42 -> 33434
B43: 80 | C43: 39 | D43: 140837 | E43: 34102 | F43: 287717 | G43: 151627 | H43: 0 | I43: 1123535 | J43: 1275162 | L43: =C43 -> 39 | N43: =E43 -> 34102 | Q43: =M43+N43+P43+O43 -> 34102
B44: 81 | C44: 40 | D44: 137914 | E44: 34785 | F44: 281746 | G44: 149832 | H44: 0 | I44: 1175442 | J44: 1325275 | L44: =C44 -> 40 | N44: =E44 -> 34785 | Q44: =M44+N44+P44+O44 -> 34785
B45: 82 | C45: 41 | D45: 135113 | E45: 35480 | F45: 276023 | G45: 147148 | H45: 0 | I45: 1230512 | J45: 1377660 | L45: =C45 -> 41 | N45: =E45 -> 35480 | Q45: =M45+N45+P45+O45 -> 35480
B46: 83 | C46: 42 | D46: 132431 | E46: 36190 | F46: 270543 | G46: 144578 | H46: 0 | I46: 1288596 | J46: 1433174 | L46: =C46 -> 42 | N46: =E46 -> 36190 | Q46: =M46+N46+P46+O46 -> 36190
B47: 84 | C47: 43 | D47: 129861 | E47: 36914 | F47: 265293 | G47: 142118 | H47: 0 | I47: 1349017 | J47: 1491135 | L47: =C47 -> 43 | N47: =E47 -> 36914 | Q47: =M47+N47+P47+O47 -> 36914
B48: 85 | C48: 44 | D48: 127401 | E48: 37652 | F48: 260268 | G48: 139764 | H48: 0 | I48: 1412733 | J48: 1552497 | L48: =C48 -> 44 | N48: =E48 -> 37652 | Q48: =M48+N48+P48+O48 -> 37652
B49: 86 | C49: 45 | D49: 125046 | E49: 38405 | F49: 255458 | G49: 137513 | H49: 0 | I49: 1479610 | J49: 1617123 | L49: =C49 -> 45 | N49: =E49 -> 38405 | Q49: =M49+N49+P49+O49 -> 38405
... B63: 100 | C63: 59 | D63: 101503 | E63: 50675 | F63: 206728 | G63: 115871 | H63: 0 | I63: 2879715 | J63: 2995585 | L63: =C63 -> 59 | N63: =E63 -> 50675 | Q63: =M63+N63+P63+O63 -> 50675
C64: 60 | D64: 100322 | E64: 51688 | F64: 204321 | G64: 114828 | H64: 0 | I64: 3024969 | J64: 3139797 | L64: =C64 -> 60 | N64: =E64 -> 51688 | Q64: =M64+N64+P64+O64 -> 51688
C65: 61 | D65: 99197 | E65: 52722 | F65: 202030 | G65: 113844 | H65: 0 | I65: 3178533 | J65: 3292376 | L65: =C65 -> 61 | N65: =E65 -> 52722 | Q65: =M65+N65+P65+O65 -> 52722
C66: 62 | D66: 98126 | E66: 53776 | F66: 199850 | G66: 112915 | H66: 0 | I66: 3341095 | J66: 3454011 | L66: =C66 -> 62 | N66: =E66 -> 53776 | Q66: =M66+N66+P66+O66 -> 53776
C67: 63 | D67: 97109 | E67: 54852 | F67: 197778 | G67: 112140 | H67: 0 | I67: 3512734 | J67: 3624874 | L67: =C67 -> 63 | N67: =E67 -> 54852 | Q67: =M67+N67+P67+O67 -> 54852
C68: 64 | D68: 96142 | E68: 55949 | F68: 195809 | G68: 111415 | H68: 0 | I68: 3694329 | J68: 3805745 | L68: =C68 -> 64 | N68: =E68 -> 55949 | Q68: =M68+N68+P68+O68 -> 55949
...

Sheet 不提取累积情况
A1: 母亲年龄 | B1: 保单年度终结 | C1: 缴付保费总额 | D1: 退保发还金额 | H1: 身故赔偿额
D2: 保证金额 | E2: 非保证金额 | G2: 总额 (A)+(B)+(C) | H2: 保证金额* (D) | I2: 非保证金额 | K2: 总额 (A)+(E)+(F) = (G) | L2: 总赔偿金额 (D 或 G) 之较高者
D3: 保证现金价值 (A) | E3: 复归红利 (B) | F3: 终期分红 (C) | I3: 复归红利 (E) | J3: 终期分红 (F)
A4: 68 | B4: 1 | C4: 30000 | D4: 31 | E4: 0 | F4: 0 | G4: 31 | H4: 31500 | I4: 0 | J4: 0 | K4: 31 | L4: 31500
A5: 69 | B5: 2 | C5: 60000 | D5: 31 | E5: 0 | F5: 0 | G5: 31 | H5: 63000 | I5: 0 | J5: 0 | K5: 31 | L5: 63000
A6: 70 | B6: 3 | C6: 90000 | D6: 7967 | E6: 2482 | F6: 4634 | G6: 15083 | H6: 94500 | I6: 2482 | J6: 4634 | K6: 15083 | L6: 94500
A7: 71 | B7: 4 | C7: 120000 | D7: 22370 | E7: 5001 | F7: 10277 | G7: 37649 | H7: 126000 | I7: 5001 | J7: 10277 | K7: 37649 | L7: 126000
A8: 72 | B8: 5 | C8: 150000 | D8: 42288 | E8: 7559 | F8: 20410 | G8: 70256 | H8: 157500 | I8: 7559 | J8: 20410 | K8: 70256 | L8: 157500
A9: 73 | B9: 6 | C9: 150000 | D9: 55771 | E9: 10154 | F9: 65534 | G9: 131460 | H9: 157500 | I9: 10154 | J9: 65534 | K9: 131460 | L9: 157500
A10: 74 | B10: 7 | C10: 150000 | D10: 68948 | E10: 12789 | F10: 69272 | G10: 151008 | H10: 157500 | I10: 12789 | J10: 69272 | K10: 151008 | L10: 157500
A11: 75 | B11: 8 | C11: 150000 | D11: 88866 | E11: 15463 | F11: 69852 | G11: 174181 | H11: 157500 | I11: 15463 | J11: 69852 | K11: 174181 | L11: 174181
A12: 76 | B12: 9 | C12: 150000 | D12: 91624 | E12: 18177 | F12: 76284 | G12: 186085 | H12: 157500 | I12: 18177 | J12: 76284 | K12: 186085 | L12: 186085
A13: 77 | B13: 10 | C13: 150000 | D13: 94076 | E13: 18745 | F13: 83897 | G13: 196717 | H13: 157500 | I13: 18745 | J13: 83897 | K13: 196717 | L13: 196717
A14: 78 | B14: 11 | C14: 150000 | D14: 97140 | E14: 19326 | F14: 94471 | G14: 210938 | H14: 157500 | I14: 19326 | J14: 94471 | K14: 210938 | L14: 210938
A15: 79 | B15: 12 | C15: 150000 | D15: 99898 | E15: 19922 | F15: 106066 | G15: 225887 | H15: 157500 | I15: 19922 | J15: 106066 | K15: 225887 | L15: 225887
... A36: 100 | B36: 33 | C36: 150000 | D36: 155976 | E36: 36435 | F36: 868432 | G36: 1060843 | H36: 157500 | I36: 36435 | J36: 868432 | K36: 1060843 | L36: 1060843
B37: 34 | C37: 150000 | D37: 156895 | E37: 37450 | F37: 935452 | G37: 1129797 | H37: 157500 | I37: 37450 | J37: 935452 | K37: 1129797 | L37: 1129797
B38: 35 | C38: 150000 | D38: 157815 | E38: 38490 | F38: 1006930 | G38: 1203234 | H38: 157815 | I38: 38490 | J38: 1006930 | K38: 1203234 | L38: 1203234
B39: 36 | C39: 150000 | D39: 158427 | E39: 39555 | F39: 1083461 | G39: 1281444 | H39: 158427 | I39: 39555 | J39: 1083461 | K39: 1281444 | L39: 1281444
B40: 37 | C40: 150000 | D40: 159653 | E40: 40647 | F40: 1164438 | G40: 1364738 | H40: 159653 | I40: 40647 | J40: 1164438 | K40: 1364738 | L40: 1364738
B41: 38 | C41: 150000 | D41: 160879 | E41: 41766 | F41: 1250802 | G41: 1453446 | H41: 160879 | I41: 41766 | J41: 1250802 | K41: 1453446 | L41: 1453446
B42: 39 | C42: 150000 | D42: 161492 | E42: 42911 | F42: 1343517 | G42: 1547920 | H42: 161492 | I42: 42911 | J42: 1343517 | K42: 1547920 | L42: 1547920
B43: 40 | C43: 150000 | D43: 162963 | E43: 44483 | F43: 1441089 | G43: 1648535 | H43: 162963 | I43: 44483 | J43: 1441089 | K43: 1648535 | L43: 1648535
B44: 41 | C44: 150000 | D44: 163361 | E44: 46063 | F44: 1546267 | G44: 1755690 | H44: 163361 | I44: 46063 | J44: 1546267 | K44: 1755690 | L44: 1755690
B45: 42 | C45: 150000 | D45: 163759 | E45: 47649 | F45: 1658402 | G45: 1869810 | H45: 163759 | I45: 47649 | J45: 1658402 | K45: 1869810 | L45: 1869810
B46: 43 | C46: 150000 | D46: 164158 | E46: 49242 | F46: 1777948 | G46: 1991348 | H46: 164158 | I46: 49242 | J46: 1777948 | K46: 1991348 | L46: 1991348
B47: 44 | C47: 150000 | D47: 164556 | E47: 50843 | F47: 1905386 | G47: 2120785 | H47: 164556 | I47: 50843 | J47: 1905386 | K47: 2120785 | L47: 2120785
B48: 45 | C48: 150000 | D48: 164954 | E48: 52451 | F48: 2041231 | G48: 2258636 | H48: 164954 | I48: 52451 | J48: 2041231 | K48: 2258636 | L48: 2258636
... B93: 90 | C93: 150000 | D93: 193974 | E93: 132807 | F93: 38095112 | G93: 38421893 | H93: 193974 | I93: 132807 | J93: 38095112 | K93: 38421893 | L93: 38421893

Sheet 提取参考：第10年9%持续提取
A1: 年龄 | B1: 保单年度终结 | C1: 缴付保费总额 | D1: 现金提取金额(1),(2) | E1: 现金提取后之基本金额 | F1: 现金提取后之退保发还金额
F2: 保证金额(2) | G2: 非保证金额 | I2: 总额 (A)+(B)+(C)
F3: 保证现金价值 (A) | G3: 复归红利 (B) | H3: 终期分红 (C) | L3: 保单年度 | M3: 保费投入 | N3: 提取金额 | O3: 优惠金额 | P3: 退保现金价值 | Q3: 现金流 | T3: 优惠比率
L4: 0 | M4: =-C5 -> -30000 | Q4: =M4+N4+P4+O4 -> -30000 | T4: 0.12
A5: =不提取累积情况!A4 -> 68 | B5: 1 | C5: 30000 | D5: 0 | E5: 306436 | F5: 31 | G5: 0 | H5: 0 | I5: 31 | L5: =B5 -> 1 | M5: =M4 -> -30000 | O5: =C5*T4 -> 3600 | Q5: =M5+N5+P5+O5 -> -26400
A6: =不提取累积情况!A5 -> 69 | B6: 2 | C6: 60000 | D6: 0 | E6: 306436 | F6: 31 | G6: 0 | H6: 0 | I6: 31 | L6: =B6 -> 2 | M6: =M5 -> -30000 | Q6: =M6+N6+P6+O6 -> -30000
A7: =不提取累积情况!A6 -> 70 | B7: 3 | C7: 90000 | D7: 0 | E7: 306436 | F7: 7967 | G7: 2482 | H7: 4634 | I7: 15083 | L7: =B7 -> 3 | M7: =M6 -> -30000 | Q7: =M7+N7+P7+O7 -> -30000
A8: =不提取累积情况!A7 -> 71 | B8: 4 | C8: 120000 | D8: 0 | E8: 306436 | F8: 22370 | G8: 5001 | H8: 10277 | I8: 37649 | L8: =B8 -> 4 | M8: =M7 -> -30000 | Q8: =M8+N8+P8+O8 -> -30000
A9: =不提取累积情况!A8 -> 72 | B9: 5 | C9: 150000 | D9: 0 | E9: 306436 | F9: 42288 | G9: 7559 | H9: 20410 | I9: 70256 | L9: =B9 -> 5 | Q9: =M9+N9+P9+O9 -> 0
A10: =不提取累积情况!A9 -> 73 | B10: 6 | C10: 150000 | D10: 0 | E10: 306436 | F10: 55771 | G10: 10154 | H10: 65534 | I10: 131460 | L10: =B10 -> 6 | N10: =D10 -> 0 | Q10: =M10+N10+P10+O10 -> 0
A11: =不提取累积情况!A10 -> 74 | B11: 7 | C11: 150000 | D11: 0 | E11: 306436 | F11: 68948 | G11: 12789 | H11: 69272 | I11: 151008 | L11: =B11 -> 7 | N11: =D11 -> 0 | Q11: =M11+N11+P11+O11 -> 0
A12: =不提取累积情况!A11 -> 75 | B12: 8 | C12: 150000 | D12: 0 | E12: 306436 | F12: 88866 | G12: 15463 | H12: 69852 | I12: 174181 | L12: =B12 -> 8 | N12: =D12 -> 0 | Q12: =M12+N12+P12+O12 -> 0
A13: =不提取累积情况!A12 -> 76 | B13: 9 | C13: 150000 | D13: 0 | E13: 306436 | F13: 91624 | G13: 18177 | H13: 76284 | I13: 186085 | L13: =B13 -> 9 | N13: =D13 -> 0 | Q13: =M13+N13+P13+O13 -> 0
A14: =不提取累积情况!A13 -> 77 | B14: 10 | C14: 150000 | D14: 13500 | E14: 306436 | F14: 94076 | G14: 8013 | H14: 81128 | I14: 183217 | L14: =B14 -> 10 | N14: =D14 -> 13500 | Q14: =M14+N14+P14+O14 -> 13500
A15: =不提取累积情况!A14 -> 78 | B15: 11 | C15: 147782 | D15: 13500 | E15: 301903 | F15: 95703 | G15: 0 | H15: 87552 | I15: 183255 | L15: =B15 -> 11 | N15: =D15 -> 13500 | Q15: =M15+N15+P15+O15 -> 13500
A16: =不提取累积情况!A15 -> 79 | B16: 12 | C16: 137751 | D16: 13500 | E16: 281411 | F16: 91740 | G16: 0 | H16: 91459 | I16: 183199 | L16: =B16 -> 12 | N16: =D16 -> 13500 | Q16: =M16+N16+P16+O16 -> 13500
A17: =不提取累积情况!A16 -> 80 | B17: 13 | C17: 128391 | D17: 13500 | E17: 262290 | F17: 88129 | G17: 0 | H17: 94949 | I17: 183078 | L17: =B17 -> 13 | N17: =D17 -> 13500 | Q17: =M17+N17+P17+O17 -> 13500
A18: =不提取累积情况!A17 -> 81 | B18: 14 | C18: 120043 | D18: 13500 | E18: 244486 | F18: 84592 | G18: 0 | H18: 98773 | I18: 183365 | L18: =B18 -> 14 | N18: =D18 -> 13500 | Q18: =M18+N18+P18+O18 -> 13500
A19: =不提取累积情况!A18 -> 82 | B19: 15 | C19: 111895 | D19: 13500 | E19: 227892 | F19: 81130 | G19: 0 | H19: 102324 | I19: 183453 | L19: =B19 -> 15 | N19: =D19 -> 13500 | Q19: =M19+N19+P19+O19 -> 13500
A20: =不提取累积情况!A19 -> 83 | B20: 16 | C20: 104335 | D20: 13500 | E20: 212496 | F20: 80748 | G20: 0 | H20: 103698 | I20: 184446 | L20: =B20 -> 16 | N20: =D20 -> 13500 | Q20: =M20+N20+P20+O20 -> 13500
A21: =不提取累积情况!A20 -> 84 | B21: 17 | C21: 97322 | D21: 13500 | E21: 198212 | F21: 80276 | G21: 0 | H21: 105250 | I21: 185526 | L21: =B21 -> 17 | N21: =D21 -> 13500 | Q21: =M21+N21+P21+O21 -> 13500
... A37: =不提取累积情况!A36 -> 100 | B37: 33 | C37: 36268 | D37: 13500 | E37: 73268 | F37: 37293 | G37: 0 | H37: 187859 | I37: 225153 | L37: =B37 -> 33 | N37: =D37 -> 13500 | Q37: =M37+N37+P37+O37 -> 13500
B38: 34 | C38: 34239 | D38: 13500 | E38: 69169 | F38: 35415 | G38: 0 | H38: 190562 | I38: 225977 | L38: =B38 -> 34 | N38: =D38 -> 13500 | Q38: =M38+N38+P38+O38 -> 13500
B39: 35 | C39: 32330 | D39: 13500 | E39: 65314 | F39: 33637 | G39: 0 | H39: 193198 | I39: 226835 | L39: =B39 -> 35 | N39: =D39 -> 13500 | Q39: =M39+N39+P39+O39 -> 13500
B40: 36 | C40: 30535 | D40: 13500 | E40: 61687 | F40: 31892 | G40: 0 | H40: 195856 | I40: 227748 | L40: =B40 -> 36 | N40: =D40 -> 13500 | Q40: =M40+N40+P40+O40 -> 13500
B41: 37 | C41: 28846 | D41: 13500 | E41: 58274 | F41: 30361 | G41: 0 | H41: 198307 | I41: 228668 | L41: =B41 -> 37 | N41: =D41 -> 13500 | Q41: =M41+N41+P41+O41 -> 13500
B42: 38 | C42: 27256 | D42: 13500 | E42: 55063 | F42: 28908 | G42: 0 | H42: 200761 | I42: 229670 | L42: =B42 -> 38 | N42: =D42 -> 13500 | Q42: =M42+N42+P42+O42 -> 13500
B43: 39 | C43: 25761 | D43: 13500 | E43: 52042 | F43: 27426 | G43: 0 | H43: 203223 | I43: 230649 | L43: =B43 -> 39 | N43: =D43 -> 13500 | Q43: =M43+N43+P43+O43 -> 13500
B44: 40 | C44: 24468 | D44: 13500 | E44: 49429 | F44: 26287 | G44: 0 | H44: 206219 | I44: 232506 | L44: =B44 -> 40 | N44: =D44 -> 13500 | Q44: =M44+N44+P44+O44 -> 13500
B45: 41 | C45: 23249 | D45: 13500 | E45: 46968 | F45: 25039 | G45: 0 | H45: 209382 | I45: 234421 | L45: =B45 -> 41 | N45: =D45 -> 13500 | Q45: =M45+N45+P45+O45 -> 13500
B46: 42 | C46: 22101 | D46: 13500 | E46: 44649 | F46: 23861 | G46: 0 | H46: 212664 | I46: 236525 | L46: =B46 -> 42 | N46: =D46 -> 13500 | Q46: =M46+N46+P46+O46 -> 13500
B47: 43 | C47: 21020 | D47: 13500 | E47: 42465 | F47: 22748 | G47: 0 | H47: 215934 | I47: 238683 | L47: =B47 -> 43 | N47: =D47 -> 13500 | Q47: =M47+N47+P47+O47 -> 13500
B48: 44 | C48: 20002 | D48: 13500 | E48: 40408 | F48: 21699 | G48: 0 | H48: 219333 | I48: 241032 | L48: =B48 -> 44 | N48: =D48 -> 13500 | Q48: =M48+N48+P48+O48 -> 13500
B49: 45 | C49: 19043 | D49: 13500 | E49: 38470 | F49: 20708 | G49: 0 | H49: 222819 | I49: 243528 | L49: =B49 -> 45 | N49: =D49 -> 13500 | Q49: =M49+N49+P49+O49 -> 13500
... B93: 89 | C93: 4918 | D93: 13500 | E93: 9836 | F93: 6207 | G93: 0 | H93: 821644 | I93: 827850 | L93: =B93 -> 89 | N93: =D93 -> 13500 | Q93: =M93+N93+P93+O93 -> 13500
B94: 90 | C94: 4865 | D94: 13500 | E94: 9729 | F94: 6159 | G94: 0 | H94: 862077 | I94: 868236 | L94: =B94 -> 90 | N94: =D94 -> 13500 | P94: =I94 -> 868236 | Q94: =M94+N94+P94+O94 -> 881736
P95: IRR= | Q95: =IRR(Q4:Q94) -> 0.061846885

Sheet 提取参考：第11年6.7%+2%通胀调增
A1: 年龄 | B1: 保单年度终结 | C1: 缴付保费总额 | D1: 现金提取金额(1),(2) | E1: 现金提取后之基本金额 | F1: 现金提取后之退保发还金额
F2: 保证金额(2) | G2: 非保证金额 | I2: 总额 (A)+(B)+(C)
F3: 保证现金价值 (A) | G3: 复归红利 (B) | H3: 终期分红 (C) | L3: 保单年度 | M3: 保费投入 | N3: 提取金额 | O3: 优惠金额 | P3: 退保现金价值 | Q3: 现金流 | T3: 优惠比例
L4: 0 | M4: =-C5 -> -30000 | Q4: =M4+N4+P4+O4 -> -30000 | T4: 0.12
A5: =不提取累积情况!A4 -> 68 | B5: 1 | C5: 30000 | D5: 0 | E5: 306436 | F5: 31 | G5: 0 | H5: 0 | I5: 31 | L5: =B5 -> 1 | M5: =M4 -> -30000 | O5: =C5*T4 -> 3600 | Q5: =M5+N5+P5+O5 -> -26400
A6: =不提取累积情况!A5 -> 69 | B6: 2 | C6: 60000 | D6: 0 | E6: 306436 | F6: 31 | G6: 0 | H6: 0 | I6: 31 | L6: =B6 -> 2 | M6: =M5 -> -30000 | Q6: =M6+N6+P6+O6 -> -30000
A7: =不提取累积情况!A6 -> 70 | B7: 3 | C7: 90000 | D7: 0 | E7: 306436 | F7: 7967 | G7: 2482 | H7: 4634 | I7: 15083 | L7: =B7 -> 3 | M7: =M6 -> -30000 | Q7: =M7+N7+P7+O7 -> -30000
A8: =不提取累积情况!A7 -> 71 | B8: 4 | C8: 120000 | D8: 0 | E8: 306436 | F8: 22370 | G8: 5001 | H8: 10277 | I8: 37649 | L8: =B8 -> 4 | M8: =M7 -> -30000 | Q8: =M8+N8+P8+O8 -> -30000
A9: =不提取累积情况!A8 -> 72 | B9: 5 | C9: 150000 | D9: 0 | E9: 306436 | F9: 42288 | G9: 7559 | H9: 20410 | I9: 70256 | L9: =B9 -> 5 | Q9: =M9+N9+P9+O9 -> 0
A10: =不提取累积情况!A9 -> 73 | B10: 6 | C10: 150000 | D10: 0 | E10: 306436 | F10: 55771 | G10: 10154 | H10: 65534 | I10: 131460 | L10: =B10 -> 6 | N10: =D10 -> 0 | Q10: =M10+N10+P10+O10 -> 0
A11: =不提取累积情况!A10 -> 74 | B11: 7 | C11: 150000 | D11: 0 | E11: 306436 | F11: 68948 | G11: 12789 | H11: 69272 | I11: 151008 | L11: =B11 -> 7 | N11: =D11 -> 0 | Q11: =M11+N11+P11+O11 -> 0
A12: =不提取累积情况!A11 -> 75 | B12: 8 | C12: 150000 | D12: 0 | E12: 306436 | F12: 88866 | G12: 15463 | H12: 69852 | I12: 174181 | L12: =B12 -> 8 | N12: =D12 -> 0 | Q12: =M12+N12+P12+O12 -> 0
A13: =不提取累积情况!A12 -> 76 | B13: 9 | C13: 150000 | D13: 0 | E13: 306436 | F13: 91624 | G13: 18177 | H13: 76284 | I13: 186085 | L13: =B13 -> 9 | N13: =D13 -> 0 | Q13: =M13+N13+P13+O13 -> 0
A14: =不提取累积情况!A13 -> 77 | B14: 10 | C14: 150000 | D14: 0 | E14: 306436 | F14: 94076 | G14: 18745 | H14: 83897 | I14: 196717 | L14: =B14 -> 10 | N14: =D14 -> 0 | Q14: =M14+N14+P14+O14 -> 0
A15: =不提取累积情况!A14 -> 78 | B15: 11 | C15: 150000 | D15: 10000 | E15: 306436 | F15: 97140 | G15: 11574 | H15: 92223 | I15: 200938 | L15: =B15 -> 11 | N15: =D15 -> 10000 | Q15: =M15+N15+P15+O15 -> 10000
A16: =不提取累积情况!A15 -> 79 | B16: 12 | C16: 150000 | D16: 10200 | E16: 306436 | F16: 99898 | G16: 4282 | H16: 100983 | I16: 205164 | L16: =B16 -> 12 | N16: =D16 -> 10200 | Q16: =M16+N16+P16+O16 -> 10200
A17: =不提取累积情况!A16 -> 80 | B17: 13 | C17: 147012 | D17: 10404 | E17: 300331 | F17: 100911 | G17: 0 | H17: 108720 | I17: 209631 | L17: =B17 -> 13 | N17: =D17 -> 10404 | Q17: =M17+N17+P17+O17 -> 10404
A18: =不提取累积情况!A17 -> 81 | B18: 14 | C18: 140196 | D18: 10612 | E18: 286406 | F18: 99097 | G18: 0 | H18: 115708 | I18: 214805 | L18: =B18 -> 14 | N18: =D18 -> 10612 | Q18: =M18+N18+P18+O18 -> 10612
A19: =不提取累积情况!A18 -> 82 | B19: 15 | C19: 133715 | D19: 10824 | E19: 273167 | F19: 97247 | G19: 0 | H19: 122652 | I19: 219899 | L19: =B19 -> 15 | N19: =D19 -> 10824 | Q19: =M19+N19+P19+O19 -> 10824
A20: =不提取累积情况!A19 -> 83 | B20: 16 | C20: 127580 | D20: 11041 | E20: 260634 | F20: 99041 | G20: 0 | H20: 127189 | I20: 226230 | L20: =B20 -> 16 | N20: =D20 -> 11041 | Q20: =M20+N20+P20+O20 -> 11041
A21: =不提取累积情况!A20 -> 84 | B21: 17 | C21: 122147 | D21: 11262 | E21: 248772 | F21: 100753 | G21: 0 | H21: 132098 | I21: 232851 | L21: =B21 -> 17 | N21: =D21 -> 11262 | Q21: =M21+N21+P21+O21 -> 11262
... A37: =不提取累积情况!A36 -> 100 | B37: 33 | C37: 63649 | D37: 15460 | E37: 129237 | F37: 65782 | G37: 0 | H37: 331365 | I37: 397147 | L37: =B37 -> 33 | N37: =D37 -> 15460 | Q37: =M37+N37+P37+O37 -> 15460
B38: 34 | C38: 61302 | D38: 15769 | E38: 124470 | F38: 63729 | G38: 0 | H38: 342915 | I38: 406644 | L38: =B38 -> 34 | N38: =D38 -> 15769 | Q38: =M38+N38+P38+O38 -> 15769
B39: 35 | C39: 59049 | D39: 16084 | E39: 119896 | F39: 61746 | G39: 0 | H39: 354651 | I39: 416398 | L39: =B39 -> 35 | N39: =D39 -> 16084 | Q39: =M39+N39+P39+O39 -> 16084
B40: 36 | C40: 56887 | D40: 16406 | E40: 115506 | F40: 59717 | G40: 0 | H40: 366732 | I40: 426449 | L40: =B40 -> 36 | N40: =D40 -> 16406 | Q40: =M40+N40+P40+O40 -> 16406
B41: 37 | C41: 54812 | D41: 16734 | E41: 111294 | F41: 57984 | G41: 0 | H41: 378732 | I41: 436716 | L41: =B41 -> 37 | N41: =D41 -> 16734 | Q41: =M41+N41+P41+O41 -> 16734
B42: 38 | C42: 52821 | D42: 17069 | E42: 107251 | F42: 56307 | G42: 0 | H42: 391036 | I42: 447343 | L42: =B42 -> 38 | N42: =D42 -> 17069 | Q42: =M42+N42+P42+O42 -> 17069
B43: 39 | C43: 50910 | D43: 17410 | E43: 103370 | F43: 54476 | G43: 0 | H43: 403660 | I43: 458136 | L43: =B43 -> 39 | N43: =D43 -> 17410 | Q43: =M43+N43+P43+O43 -> 17410
B44: 40 | C44: 49302 | D44: 17758 | E44: 100106 | F44: 53237 | G44: 0 | H44: 417643 | I44: 470880 | L44: =B44 -> 40 | N44: =D44 -> 17758 | Q44: =M44+N44+P44+O44 -> 17758
B45: 41 | C45: 47758 | D45: 18114 | E45: 96970 | F45: 51695 | G45: 0 | H45: 432291 | I45: 483985 | L45: =B45 -> 41 | N45: =D45 -> 18114 | Q45: =M45+N45+P45+O45 -> 18114
B46: 42 | C46: 46274 | D46: 18476 | E46: 93957 | F46: 50210 | G46: 0 | H46: 447515 | I46: 497726 | L46: =B46 -> 42 | N46: =D46 -> 18476 | Q46: =M46+N46+P46+O46 -> 18476
B47: 43 | C47: 44848 | D47: 18845 | E47: 91062 | F47: 48782 | G47: 0 | H47: 463048 | I47: 511830 | L47: =B47 -> 43 | N47: =D47 -> 18845 | Q47: =M47+N47+P47+O47 -> 18845
B48: 44 | C48: 43478 | D48: 19222 | E48: 88281 | F48: 47407 | G48: 0 | H48: 479187 | I48: 526594 | L48: =B48 -> 44 | N48: =D48 -> 19222 | Q48: =M48+N48+P48+O48 -> 19222
B49: 45 | C49: 42163 | D49: 19607 | E49: 85610 | F49: 46084 | G49: 0 | H49: 495851 | I49: 541934 | L49: =B49 -> 45 | N49: =D49 -> 19607 | Q49: =M49+N49+P49+O49 -> 19607
... B103: 99 | C103: 14712 | D103: 57124 | E103: 29424 | F103: 19478 | G103: 0 | H103: 4427475 | I103: 4446954 | L103: =B103 -> 99 | N103: =D103 -> 57124 | Q103: =M103+N103+P103+O103 -> 57124
B104: 100 | C104: 14596 | D104: 58266 | E104: 29193 | F104: 19442 | G104: 0 | H104: 4658526 | I104: 4677968 | L104: =B104 -> 100 | N104: =D104 -> 58266 | P104: =I104 -> 4677968 | Q104: =M104+N104+P104+O104 -> 4736234
P105: IRR= | Q105: =IRR(Q4:Q104) -> 0.063841472

Sheet 提取参考：第15年9%通胀调增
A1: 母亲年龄 | B1: 保单年度终结 | C1: 缴付保费总额 | D1: 现金提取金额(1),(2) | E1: 现金提取后之基本金额 | F1: 现金提取后之退保发还金额
F2: 保证金额(2) | G2: 非保证金额 | I2: 总额 (A)+(B)+(C)
F3: 保证现金价值 (A) | G3: 复归红利 (B) | H3: 终期分红 (C) | L3: 保单年度 | M3: 保费投入 | N3: 提取金额 | O3: 优惠金额 | P3: 退保现金价值 | Q3: 现金流 | T3: 优惠比率
L4: 0 | M4: =-C5 -> -30000 | Q4: =M4+N4+P4+O4 -> -30000 | T4: 0.12
A5: =不提取累积情况!A4 -> 68 | B5: 1 | C5: 30000 | D5: 0 | E5: 306436 | F5: 31 | G5: 0 | H5: 0 | I5: 31 | L5: =B5 -> 1 | M5: =M4 -> -30000 | O5: =C5*T4 -> 3600 | Q5: =M5+N5+P5+O5 -> -26400
A6: =不提取累积情况!A5 -> 69 | B6: 2 | C6: 60000 | D6: 0 | E6: 306436 | F6: 31 | G6: 0 | H6: 0 | I6: 31 | L6: =B6 -> 2 | M6: =M5 -> -30000 | Q6: =M6+N6+P6+O6 -> -30000
A7: =不提取累积情况!A6 -> 70 | B7: 3 | C7: 90000 | D7: 0 | E7: 306436 | F7: 7967 | G7: 2482 | H7: 4634 | I7: 15083 | L7: =B7 -> 3 | M7: =M6 -> -30000 | Q7: =M7+N7+P7+O7 -> -30000
A8: =不提取累积情况!A7 -> 71 | B8: 4 | C8: 120000 | D8: 0 | E8: 306436 | F8: 22370 | G8: 5001 | H8: 10277 | I8: 37649 | L8: =B8 -> 4 | M8: =M7 -> -30000 | Q8: =M8+N8+P8+O8 -> -30000
A9: =不提取累积情况!A8 -> 72 | B9: 5 | C9: 150000 | D9: 0 | E9: 306436 | F9: 42288 | G9: 7559 | H9: 20410 | I9: 70256 | L9: =B9 -> 5 | Q9: =M9+N9+P9+O9 -> 0
A10: =不提取累积情况!A9 -> 73 | B10: 6 | C10: 150000 | D10: 0 | E10: 306436 | F10: 55771 | G10: 10154 | H10: 65534 | I10: 131460 | L10: =B10 -> 6 | N10: =D10 -> 0 | Q10: =M10+N10+P10+O10 -> 0
A11: =不提取累积情况!A10 -> 74 | B11: 7 | C11: 150000 | D11: 0 | E11: 306436 | F11: 68948 | G11: 12789 | H11: 69272 | I11: 151008 | L11: =B11 -> 7 | N11: =D11 -> 0 | Q11: =M11+N11+P11+O11 -> 0
A12: =不提取累积情况!A11 -> 75 | B12: 8 | C12: 150000 | D12: 0 | E12: 306436 | F12: 88866 | G12: 15463 | H12: 69852 | I12: 174181 | L12: =B12 -> 8 | N12: =D12 -> 0 | Q12: =M12+N12+P12+O12 -> 0
A13: =不提取累积情况!A12 -> 76 | B13: 9 | C13: 150000 | D13: 0 | E13: 306436 | F13: 91624 | G13: 18177 | H13: 76284 | I13: 186085 | L13: =B13 -> 9 | N13: =D13 -> 0 | Q13: =M13+N13+P13+O13 -> 0
A14: =不提取累积情况!A13 -> 77 | B14: 10 | C14: 150000 | D14: 0 | E14: 306436 | F14: 94076 | G14: 18745 | H14: 83897 | I14: 196717 | L14: =B14 -> 10 | N14: =D14 -> 0 | Q14: =M14+N14+P14+O14 -> 0
A15: =不提取累积情况!A14 -> 78 | B15: 11 | C15: 150000 | D15: 0 | E15: 306436 | F15: 97140 | G15: 19326 | H15: 94471 | I15: 210938 | L15: =B15 -> 11 | N15: =D15 -> 0 | Q15: =M15+N15+P15+O15 -> 0
A16: =不提取累积情况!A15 -> 79 | B16: 12 | C16: 150000 | D16: 0 | E16: 306436 | F16: 99898 | G16: 19922 | H16: 106066 | I16: 225887 | L16: =B16 -> 12 | N16: =D16 -> 0 | Q16: =M16+N16+P16+O16 -> 0
A17: =不提取累积情况!A16 -> 80 | B17: 13 | C17: 150000 | D17: 0 | E17: 306436 | F17: 102962 | G17: 20533 | H17: 118363 | I17: 241858 | L17: =B17 -> 13 | N17: =D17 -> 0 | Q17: =M17+N17+P17+O17 -> 0
A18: =不提取累积情况!A17 -> 81 | B18: 14 | C18: 150000 | D18: 0 | E18: 306436 | F18: 106027 | G18: 21159 | H18: 132348 | I18: 259534 | L18: =B18 -> 14 | N18: =D18 -> 0 | Q18: =M18+N18+P18+O18 -> 0
A19: =不提取累积情况!A18 -> 82 | B19: 15 | C19: 150000 | D19: 14000 | E19: 306436 | F19: 109091 | G19: 12138 | H19: 143040 | I19: 264269 | L19: =B19 -> 15 | N19: =D19 -> 14000 | Q19: =M19+N19+P19+O19 -> 14000
A20: =不提取累积情况!A19 -> 83 | B20: 16 | C20: 150000 | D20: 14280 | E20: 306436 | F20: 116446 | G20: 2961 | H20: 150986 | I20: 270392 | L20: =B20 -> 16 | N20: =D20 -> 14280 | Q20: =M20+N20+P20+O20 -> 14280
A21: =不提取累积情况!A20 -> 84 | B21: 17 | C21: 144910 | D21: 14566 | E21: 296037 | F21: 119895 | G21: 0 | H21: 157195 | I21: 277090 | L21: =B21 -> 17 | N21: =D21 -> 14566 | Q21: =M21+N21+P21+O21 -> 14566
... A37: =不提取累积情况!A36 -> 100 | B37: 33 | C37: 69551 | D37: 19995 | E37: 141220 | F37: 71881 | G37: 0 | H37: 362088 | I37: 433969 | L37: =B37 -> 33 | N37: =D37 -> 19995 | Q37: =M37+N37+P37+O37 -> 19995
B38: 34 | C38: 66508 | D38: 20395 | E38: 135042 | F38: 69142 | G38: 0 | H38: 372041 | I38: 441183 | L38: =B38 -> 34 | N38: =D38 -> 20395 | Q38: =M38+N38+P38+O38 -> 20395
B39: 35 | C39: 63589 | D39: 20803 | E39: 129114 | F39: 66494 | G39: 0 | H39: 381918 | I39: 448412 | L39: =B39 -> 35 | N39: =D39 -> 20803 | Q39: =M39+N39+P39+O39 -> 20803
B40: 36 | C40: 60787 | D40: 21219 | E40: 123425 | F40: 63811 | G40: 0 | H40: 391874 | I40: 455685 | L40: =B40 -> 36 | N40: =D40 -> 21219 | Q40: =M40+N40+P40+O40 -> 21219
B41: 37 | C41: 58098 | D41: 21644 | E41: 117964 | F41: 61459 | G41: 0 | H41: 401433 | I41: 462892 | L41: =B41 -> 37 | N41: =D41 -> 21644 | Q41: =M41+N41+P41+O41 -> 21644
B42: 38 | C42: 55517 | D42: 22077 | E42: 112724 | F42: 59180 | G42: 0 | H42: 410992 | I42: 470172 | L42: =B42 -> 38 | N42: =D42 -> 22077 | Q42: =M42+N42+P42+O42 -> 22077
B43: 39 | C43: 53039 | D43: 22518 | E43: 107693 | F43: 56754 | G43: 0 | H43: 420542 | I43: 477296 | L43: =B43 -> 39 | N43: =D43 -> 22518 | Q43: =M43+N43+P43+O43 -> 22518
B44: 40 | C44: 50897 | D44: 22968 | E44: 103343 | F44: 54958 | G44: 0 | H44: 431148 | I44: 486106 | L44: =B44 -> 40 | N44: =D44 -> 22968 | Q44: =M44+N44+P44+O44 -> 22968
B45: 41 | C45: 48835 | D45: 23428 | E45: 99158 | F45: 52861 | G45: 0 | H45: 442045 | I45: 494906 | L45: =B45 -> 41 | N45: =D45 -> 23428 | Q45: =M45+N45+P45+O45 -> 23428
B46: 42 | C46: 46853 | D46: 23896 | E46: 95132 | F46: 50839 | G46: 0 | H46: 453115 | I46: 503954 | L46: =B46 -> 42 | N46: =D46 -> 23896 | Q46: =M46+N46+P46+O46 -> 23896
B47: 43 | C47: 44945 | D47: 24374 | E47: 91259 | F47: 48888 | G47: 0 | H47: 464053 | I47: 512941 | L47: =B47 -> 43 | N47: =D47 -> 24374 | Q47: =M47+N47+P47+O47 -> 24374
B48: 44 | C48: 43110 | D48: 24862 | E48: 87534 | F48: 47006 | G48: 0 | H48: 475134 | I48: 522139 | L48: =B48 -> 44 | N48: =D48 -> 24862 | Q48: =M48+N48+P48+O48 -> 24862
B49: 45 | C49: 41346 | D49: 25359 | E49: 83950 | F49: 45191 | G49: 0 | H49: 486241 | I49: 531432 | L49: =B49 -> 45 | N49: =D49 -> 25359 | Q49: =M49+N49+P49+O49 -> 25359
... B103: 99 | C103: 1884 | D103: 73883 | E103: 3768 | F103: 2495 | G103: 0 | H103: 567010 | I103: 569504 | L103: =B103 -> 99 | N103: =D103 -> 73883 | Q103: =M103+N103+P103+O103 -> 73883
B104: 100 | C104: 1657 | D104: 75360 | E104: 3315 | F104: 2208 | G104: 0 | H104: 528983 | I104: 531191 | L104: =B104 -> 100 | N104: =D104 -> 75360 | P104: =I104 -> 531191 | Q104: =M104+N104+P104+O104 -> 606551
P105: IRR= | Q105: =IRR(Q4:Q104) -> 0.064336891

Sheet 提取参考：第18年15%持续提取
A1: 母亲年龄 | B1: 保单年度终结 | C1: 缴付保费总额 | D1: 现金提取金额(1),(2) | E1: 现金提取后之基本金额 | F1: 现金提取后之退保发还金额
F2: 保证金额(2) | G2: 非保证金额 | I2: 总额 (A)+(B)+(C)
F3: 保证现金价值 (A) | G3: 复归红利 (B) | H3: 终期分红 (C) | L3: 保单年度 | M3: 保费投入 | N3: 提取金额 | O3: 优惠金额 | P3: 退保现金价值 | Q3: 现金流 | T3: 优惠比率
L4: 0 | M4: =-C5 -> -30000 | Q4: =M4+N4+P4+O4 -> -30000 | T4: 0.12
A5: =不提取累积情况!A4 -> 68 | B5: 1 | C5: 30000 | D5: 0 | E5: 306436 | F5: 31 | G5: 0 | H5: 0 | I5: 31 | L5: =B5 -> 1 | M5: =M4 -> -30000 | O5: =C5*T4 -> 3600 | Q5: =M5+N5+P5+O5 -> -26400
A6: =不提取累积情况!A5 -> 69 | B6: 2 | C6: 60000 | D6: 0 | E6: 306436 | F6: 31 | G6: 0 | H6: 0 | I6: 31 | L6: =B6 -> 2 | M6: =M5 -> -30000 | Q6: =M6+N6+P6+O6 -> -30000
A7: =不提取累积情况!A6 -> 70 | B7: 3 | C7: 90000 | D7: 0 | E7: 306436 | F7: 7967 | G7: 2482 | H7: 4634 | I7: 15083 | L7: =B7 -> 3 | M7: =M6 -> -30000 | Q7: =M7+N7+P7+O7 -> -30000
A8: =不提取累积情况!A7 -> 71 | B8: 4 | C8: 120000 | D8: 0 | E8: 306436 | F8: 22370 | G8: 5001 | H8: 10277 | I8: 37649 | L8: =B8 -> 4 | M8: =M7 -> -30000 | Q8: =M8+N8+P8+O8 -> -30000
A9: =不提取累积情况!A8 -> 72 | B9: 5 | C9: 150000 | D9: 0 | E9: 306436 | F9: 42288 | G9: 7559 | H9: 20410 | I9: 70256 | L9: =B9 -> 5 | Q9: =M9+N9+P9+O9 -> 0
A10: =不提取累积情况!A9 -> 73 | B10: 6 | C10: 150000 | D10: 0 | E10: 306436 | F10: 55771 | G10: 10154 | H10: 65534 | I10: 131460 | L10: =B10 -> 6 | N10: =D10 -> 0 | Q10: =M10+N10+P10+O10 -> 0
A11: =不提取累积情况!A10 -> 74 | B11: 7 | C11: 150000 | D11: 0 | E11: 306436 | F11: 68948 | G11: 12789 | H11: 69272 | I11: 151008 | L11: =B11 -> 7 | N11: =D11 -> 0 | Q11: =M11+N11+P11+O11 -> 0
A12: =不提取累积情况!A11 -> 75 | B12: 8 | C12: 150000 | D12: 0 | E12: 306436 | F12: 88866 | G12: 15463 | H12: 69852 | I12: 174181 | L12: =B12 -> 8 | N12: =D12 -> 0 | Q12: =M12+N12+P12+O12 -> 0
A13: =不提取累积情况!A12 -> 76 | B13: 9 | C13: 150000 | D13: 0 | E13: 306436 | F13: 91624 | G13: 18177 | H13: 76284 | I13: 186085 | L13: =B13 -> 9 | N13: =D13 -> 0 | Q13: =M13+N13+P13+O13 -> 0
A14: =不提取累积情况!A13 -> 77 | B14: 10 | C14: 150000 | D14: 0 | E14: 306436 | F14: 94076 | G14: 18745 | H14: 83897 | I14: 196717 | L14: =B14 -> 10 | N14: =D14 -> 0 | Q14: =M14+N14+P14+O14 -> 0
A15: =不提取累积情况!A14 -> 78 | B15: 11 | C15: 150000 | D15: 0 | E15: 306436 | F15: 97140 | G15: 19326 | H15: 94471 | I15: 210938 | L15: =B15 -> 11 | N15: =D15 -> 0 | Q15: =M15+N15+P15+O15 -> 0
A16: =不提取累积情况!A15 -> 79 | B16: 12 | C16: 150000 | D16: 0 | E16: 306436 | F16: 99898 | G16: 19922 | H16: 106066 | I16: 225887 | L16: =B16 -> 12 | N16: =D16 -> 0 | Q16: =M16+N16+P16+O16 -> 0
A17: =不提取累积情况!A16 -> 80 | B17: 13 | C17: 150000 | D17: 0 | E17: 306436 | F17: 102962 | G17: 20533 | H17: 118363 | I17: 241858 | L17: =B17 -> 13 | N17: =D17 -> 0 | Q17: =M17+N17+P17+O17 -> 0
A18: =不提取累积情况!A17 -> 81 | B18: 14 | C18: 150000 | D18: 0 | E18: 306436 | F18: 106027 | G18: 21159 | H18: 132348 | I18: 259534 | L18: =B18 -> 14 | N18: =D18 -> 0 | Q18: =M18+N18+P18+O18 -> 0
A19: =不提取累积情况!A18 -> 82 | B19: 15 | C19: 150000 | D19: 0 | E19: 306436 | F19: 109091 | G19: 21800 | H19: 147378 | I19: 278269 | L19: =B19 -> 15 | N19: =D19 -> 0 | Q19: =M19+N19+P19+O19 -> 0
A20: =不提取累积情况!A19 -> 83 | B20: 16 | C20: 150000 | D20: 0 | E20: 306436 | F20: 116446 | G20: 22456 | H20: 160499 | I20: 299402 | L20: =B20 -> 16 | N20: =D20 -> 0 | Q20: =M20+N20+P20+O20 -> 0
A21: =不提取累积情况!A20 -> 84 | B21: 17 | C21: 150000 | D21: 0 | E21: 306436 | F21: 124107 | G21: 23129 | H21: 174999 | I21: 322235 | L21: =B21 -> 17 | N21: =D21 -> 0 | Q21: =M21+N21+P21+O21 -> 0
... A37: =不提取累积情况!A36 -> 100 | B37: 33 | C37: 65887 | D37: 22500 | E37: 133780 | F37: 68094 | G37: 0 | H37: 343013 | I37: 411107 | L37: =B37 -> 33 | N37: =D37 -> 22500 | Q37: =M37+N37+P37+O37 -> 22500
B38: 34 | C38: 62525 | D38: 22500 | E38: 126955 | F38: 65001 | G38: 0 | H38: 349761 | I38: 414761 | L38: =B38 -> 34 | N38: =D38 -> 22500 | Q38: =M38+N38+P38+O38 -> 22500
B39: 35 | C39: 59363 | D39: 22500 | E39: 120534 | F39: 62075 | G39: 0 | H39: 356540 | I39: 418615 | L39: =B39 -> 35 | N39: =D39 -> 22500 | Q39: =M39+N39+P39+O39 -> 22500
B40: 36 | C40: 56389 | D40: 22500 | E40: 114494 | F40: 59194 | G40: 0 | H40: 363520 | I40: 422713 | L40: =B40 -> 36 | N40: =D40 -> 22500 | Q40: =M40+N40+P40+O40 -> 22500
B41: 37 | C41: 53590 | D41: 22500 | E41: 108812 | F41: 56691 | G41: 0 | H41: 370287 | I41: 426978 | L41: =B41 -> 37 | N41: =D41 -> 22500 | Q41: =M41+N41+P41+O41 -> 22500
B42: 38 | C42: 50957 | D42: 22500 | E42: 103466 | F42: 54320 | G42: 0 | H42: 377237 | I42: 431556 | L42: =B42 -> 38 | N42: =D42 -> 22500 | Q42: =M42+N42+P42+O42 -> 22500
B43: 39 | C43: 48479 | D43: 22500 | E43: 98435 | F43: 51875 | G43: 0 | H43: 384389 | I43: 436264 | L43: =B43 -> 39 | N43: =D43 -> 22500 | Q43: =M43+N43+P43+O43 -> 22500
B44: 40 | C44: 46363 | D44: 22500 | E44: 94139 | F44: 50063 | G44: 0 | H44: 392747 | I44: 442810 | L44: =B44 -> 40 | N44: =D44 -> 22500 | Q44: =M44+N44+P44+O44 -> 22500
B45: 41 | C45: 44371 | D45: 22500 | E45: 90094 | F45: 48029 | G45: 0 | H45: 401639 | I45: 449668 | L45: =B45 -> 41 | N45: =D45 -> 22500 | Q45: =M45+N45+P45+O45 -> 22500
B46: 42 | C46: 42497 | D46: 22500 | E46: 86288 | F46: 46112 | G46: 0 | H46: 410988 | I46: 457100 | L46: =B46 -> 42 | N46: =D46 -> 22500 | Q46: =M46+N46+P46+O46 -> 22500
B47: 43 | C47: 40732 | D47: 22500 | E47: 82705 | F47: 44305 | G47: 0 | H47: 420555 | I47: 464860 | L47: =B47 -> 43 | N47: =D47 -> 22500 | Q47: =M47+N47+P47+O47 -> 22500
B48: 44 | C48: 39072 | D48: 22500 | E48: 79334 | F48: 42602 | G48: 0 | H48: 430625 | I48: 473227 | L48: =B48 -> 44 | N48: =D48 -> 22500 | Q48: =M48+N48+P48+O48 -> 22500
B49: 45 | C49: 37510 | D49: 22500 | E49: 76163 | F49: 40998 | G49: 0 | H49: 441134 | I49: 482133 | L49: =B49 -> 45 | N49: =D49 -> 22500 | Q49: =M49+N49+P49+O49 -> 22500
... B103: 99 | C103: 15282 | D103: 22500 | E103: 30565 | F103: 20234 | G103: 0 | H103: 4599210 | I103: 4619444 | L103: =B103 -> 99 | N103: =D103 -> 22500 | Q103: =M103+N103+P103+O103 -> 22500
B104: 100 | C104: 15281 | D104: 22500 | E104: 30562 | F104: 20354 | G104: 0 | H104: 4877091 | I104: 4897445 | L104: =B104 -> 100 | N104: =D104 -> 22500 | P104: =I104 -> 4897445 | Q104: =M104+N104+P104+O104 -> 4919945
P105: IRR= | Q105: =IRR(Q4:Q104) -> 0.064456988
